NAMESPACE                   LAST SEEN   TYPE      REASON                    OBJECT                                                      MESSAGE
default                     43m         Normal    Starting                  node/bijux-atlas-e2e-control-plane                          
kube-system                 44m         Normal    Pulled                    pod/etcd-bijux-atlas-e2e-control-plane                      Container image "registry.k8s.io/etcd:3.5.16-0" already present on machine
kube-system                 44m         Normal    Created                   pod/kube-scheduler-bijux-atlas-e2e-control-plane            Created container: kube-scheduler
kube-system                 44m         Normal    Pulled                    pod/kube-scheduler-bijux-atlas-e2e-control-plane            Container image "registry.k8s.io/kube-scheduler:v1.32.2" already present on machine
kube-system                 44m         Normal    Pulled                    pod/kube-controller-manager-bijux-atlas-e2e-control-plane   Container image "registry.k8s.io/kube-controller-manager:v1.32.2" already present on machine
kube-system                 44m         Normal    Pulled                    pod/kube-apiserver-bijux-atlas-e2e-control-plane            Container image "registry.k8s.io/kube-apiserver:v1.32.2" already present on machine
default                     44m         Normal    NodeAllocatableEnforced   node/bijux-atlas-e2e-control-plane                          Updated Node Allocatable limit across pods
default                     44m         Normal    NodeHasSufficientPID      node/bijux-atlas-e2e-control-plane                          Node bijux-atlas-e2e-control-plane status is now: NodeHasSufficientPID
default                     44m         Normal    NodeHasNoDiskPressure     node/bijux-atlas-e2e-control-plane                          Node bijux-atlas-e2e-control-plane status is now: NodeHasNoDiskPressure
default                     44m         Normal    NodeHasSufficientMemory   node/bijux-atlas-e2e-control-plane                          Node bijux-atlas-e2e-control-plane status is now: NodeHasSufficientMemory
kube-system                 44m         Normal    Started                   pod/etcd-bijux-atlas-e2e-control-plane                      Started container etcd
kube-system                 44m         Normal    Created                   pod/kube-controller-manager-bijux-atlas-e2e-control-plane   Created container: kube-controller-manager
kube-system                 44m         Normal    Started                   pod/kube-scheduler-bijux-atlas-e2e-control-plane            Started container kube-scheduler
kube-system                 44m         Normal    Started                   pod/kube-controller-manager-bijux-atlas-e2e-control-plane   Started container kube-controller-manager
kube-system                 44m         Normal    Created                   pod/kube-apiserver-bijux-atlas-e2e-control-plane            Created container: kube-apiserver
kube-system                 44m         Normal    Started                   pod/kube-apiserver-bijux-atlas-e2e-control-plane            Started container kube-apiserver
kube-system                 44m         Normal    Created                   pod/etcd-bijux-atlas-e2e-control-plane                      Created container: etcd
default                     44m         Normal    NodeAllocatableEnforced   node/bijux-atlas-e2e-control-plane                          Updated Node Allocatable limit across pods
default                     44m         Normal    Starting                  node/bijux-atlas-e2e-control-plane                          Starting kubelet.
default                     44m         Normal    NodeHasSufficientMemory   node/bijux-atlas-e2e-control-plane                          Node bijux-atlas-e2e-control-plane status is now: NodeHasSufficientMemory
default                     44m         Normal    NodeHasNoDiskPressure     node/bijux-atlas-e2e-control-plane                          Node bijux-atlas-e2e-control-plane status is now: NodeHasNoDiskPressure
kube-system                 44m         Warning   Unhealthy                 pod/kube-scheduler-bijux-atlas-e2e-control-plane            Readiness probe failed: HTTP probe failed with statuscode: 500
default                     44m         Normal    NodeHasSufficientPID      node/bijux-atlas-e2e-control-plane                          Node bijux-atlas-e2e-control-plane status is now: NodeHasSufficientPID
kube-system                 44m         Normal    LeaderElection            lease/kube-controller-manager                               bijux-atlas-e2e-control-plane_1ca9505c-ffd9-467f-9e3a-1934e343239c became leader
kube-system                 44m         Normal    LeaderElection            lease/kube-scheduler                                        bijux-atlas-e2e-control-plane_c42daf9f-5b15-43cc-ae1c-9f4887485024 became leader
kube-system                 43m         Normal    ScalingReplicaSet         deployment/coredns                                          Scaled up replica set coredns-668d6bf9bc from 0 to 2
default                     43m         Normal    RegisteredNode            node/bijux-atlas-e2e-control-plane                          Node bijux-atlas-e2e-control-plane event: Registered Node bijux-atlas-e2e-control-plane in Controller
atlas-e2e                   43m         Normal    ScalingReplicaSet         deployment/grafana                                          Scaled up replica set grafana-7459f79596 from 0 to 1
kube-system                 43m         Normal    Scheduled                 pod/kindnet-62s5l                                           Successfully assigned kube-system/kindnet-62s5l to bijux-atlas-e2e-control-plane
kube-system                 43m         Warning   FailedMount               pod/kindnet-62s5l                                           MountVolume.SetUp failed for volume "kube-api-access-5r49n" : configmap "kube-root-ca.crt" not found
kube-system                 43m         Normal    SuccessfulCreate          daemonset/kindnet                                           Created pod: kindnet-62s5l
kube-system                 43m         Normal    Scheduled                 pod/kube-proxy-7mf97                                        Successfully assigned kube-system/kube-proxy-7mf97 to bijux-atlas-e2e-control-plane
kube-system                 43m         Warning   FailedMount               pod/kube-proxy-7mf97                                        MountVolume.SetUp failed for volume "kube-api-access-5smq6" : configmap "kube-root-ca.crt" not found
atlas-e2e                   43m         Normal    ScalingReplicaSet         deployment/prometheus                                       Scaled up replica set prometheus-77f7b9d779 from 0 to 1
atlas-e2e                   43m         Normal    ScalingReplicaSet         deployment/otel-collector                                   Scaled up replica set otel-collector-676699486c from 0 to 1
atlas-e2e                   43m         Normal    ScalingReplicaSet         deployment/minio                                            Scaled up replica set minio-8d4866b9 from 0 to 1
kube-system                 43m         Normal    SuccessfulCreate          daemonset/kube-proxy                                        Created pod: kube-proxy-7mf97
local-path-storage          43m         Normal    ScalingReplicaSet         deployment/local-path-provisioner                           Scaled up replica set local-path-provisioner-7dc846544d from 0 to 1
kube-system                 43m         Normal    Pulled                    pod/kindnet-62s5l                                           Container image "docker.io/kindest/kindnetd:v20250214-acbabc1a" already present on machine
kube-system                 43m         Normal    Started                   pod/kube-proxy-7mf97                                        Started container kube-proxy
kube-system                 43m         Normal    Created                   pod/kube-proxy-7mf97                                        Created container: kube-proxy
atlas-e2e                   43m         Normal    SuccessfulCreate          replicaset/grafana-7459f79596                               Created pod: grafana-7459f79596-vr42j
kube-system                 43m         Normal    SuccessfulCreate          replicaset/coredns-668d6bf9bc                               Created pod: coredns-668d6bf9bc-phnlt
kube-system                 43m         Normal    Pulled                    pod/kube-proxy-7mf97                                        Container image "registry.k8s.io/kube-proxy:v1.32.2" already present on machine
local-path-storage          43m         Warning   FailedScheduling          pod/local-path-provisioner-7dc846544d-9w5nc                 0/1 nodes are available: 1 node(s) had untolerated taint {node.kubernetes.io/not-ready: }. preemption: 0/1 nodes are available: 1 Preemption is not helpful for scheduling.
atlas-e2e                   43m         Warning   FailedScheduling          pod/grafana-7459f79596-vr42j                                0/1 nodes are available: 1 node(s) had untolerated taint {node.kubernetes.io/not-ready: }. preemption: 0/1 nodes are available: 1 Preemption is not helpful for scheduling.
atlas-e2e                   43m         Warning   FailedScheduling          pod/minio-8d4866b9-gk4nn                                    0/1 nodes are available: 1 node(s) had untolerated taint {node.kubernetes.io/not-ready: }. preemption: 0/1 nodes are available: 1 Preemption is not helpful for scheduling.
kube-system                 43m         Warning   FailedScheduling          pod/coredns-668d6bf9bc-phnlt                                0/1 nodes are available: 1 node(s) had untolerated taint {node.kubernetes.io/not-ready: }. preemption: 0/1 nodes are available: 1 Preemption is not helpful for scheduling.
atlas-e2e                   43m         Warning   FailedScheduling          pod/prometheus-77f7b9d779-2zq96                             0/1 nodes are available: 1 node(s) had untolerated taint {node.kubernetes.io/not-ready: }. preemption: 0/1 nodes are available: 1 Preemption is not helpful for scheduling.
kube-system                 43m         Warning   FailedScheduling          pod/coredns-668d6bf9bc-g2c4j                                0/1 nodes are available: 1 node(s) had untolerated taint {node.kubernetes.io/not-ready: }. preemption: 0/1 nodes are available: 1 Preemption is not helpful for scheduling.
atlas-e2e                   43m         Normal    SuccessfulCreate          replicaset/otel-collector-676699486c                        Created pod: otel-collector-676699486c-xhdlz
atlas-e2e                   43m         Normal    SuccessfulCreate          replicaset/prometheus-77f7b9d779                            Created pod: prometheus-77f7b9d779-2zq96
kube-system                 43m         Normal    SuccessfulCreate          replicaset/coredns-668d6bf9bc                               Created pod: coredns-668d6bf9bc-g2c4j
atlas-e2e                   43m         Warning   FailedScheduling          pod/otel-collector-676699486c-xhdlz                         0/1 nodes are available: 1 node(s) had untolerated taint {node.kubernetes.io/not-ready: }. preemption: 0/1 nodes are available: 1 Preemption is not helpful for scheduling.
atlas-e2e                   43m         Normal    SuccessfulCreate          replicaset/minio-8d4866b9                                   Created pod: minio-8d4866b9-gk4nn
local-path-storage          43m         Normal    SuccessfulCreate          replicaset/local-path-provisioner-7dc846544d                Created pod: local-path-provisioner-7dc846544d-9w5nc
kube-system                 43m         Normal    Created                   pod/kindnet-62s5l                                           Created container: kindnet-cni
kube-system                 43m         Normal    Started                   pod/kindnet-62s5l                                           Started container kindnet-cni
atlas-e2e                   43m         Normal    Scheduled                 pod/otel-collector-676699486c-xhdlz                         Successfully assigned atlas-e2e/otel-collector-676699486c-xhdlz to bijux-atlas-e2e-control-plane
kube-system                 43m         Normal    Scheduled                 pod/coredns-668d6bf9bc-g2c4j                                Successfully assigned kube-system/coredns-668d6bf9bc-g2c4j to bijux-atlas-e2e-control-plane
kube-system                 43m         Normal    Scheduled                 pod/coredns-668d6bf9bc-phnlt                                Successfully assigned kube-system/coredns-668d6bf9bc-phnlt to bijux-atlas-e2e-control-plane
default                     43m         Normal    NodeReady                 node/bijux-atlas-e2e-control-plane                          Node bijux-atlas-e2e-control-plane status is now: NodeReady
atlas-e2e                   43m         Normal    Scheduled                 pod/prometheus-77f7b9d779-2zq96                             Successfully assigned atlas-e2e/prometheus-77f7b9d779-2zq96 to bijux-atlas-e2e-control-plane
atlas-e2e                   43m         Normal    Scheduled                 pod/minio-8d4866b9-gk4nn                                    Successfully assigned atlas-e2e/minio-8d4866b9-gk4nn to bijux-atlas-e2e-control-plane
local-path-storage          43m         Normal    Scheduled                 pod/local-path-provisioner-7dc846544d-9w5nc                 Successfully assigned local-path-storage/local-path-provisioner-7dc846544d-9w5nc to bijux-atlas-e2e-control-plane
atlas-e2e                   43m         Normal    Scheduled                 pod/grafana-7459f79596-vr42j                                Successfully assigned atlas-e2e/grafana-7459f79596-vr42j to bijux-atlas-e2e-control-plane
atlas-e2e                   43m         Normal    Pulling                   pod/otel-collector-676699486c-xhdlz                         Pulling image "otel/opentelemetry-collector-contrib:0.111.0"
kube-system                 43m         Normal    Started                   pod/coredns-668d6bf9bc-phnlt                                Started container coredns
kube-system                 43m         Normal    Started                   pod/coredns-668d6bf9bc-g2c4j                                Started container coredns
local-path-storage          43m         Normal    Pulled                    pod/local-path-provisioner-7dc846544d-9w5nc                 Container image "docker.io/kindest/local-path-provisioner:v20250214-acbabc1a" already present on machine
local-path-storage          43m         Normal    Created                   pod/local-path-provisioner-7dc846544d-9w5nc                 Created container: local-path-provisioner
atlas-e2e                   43m         Normal    Pulling                   pod/prometheus-77f7b9d779-2zq96                             Pulling image "prom/prometheus:v2.54.1"
kube-system                 43m         Normal    Created                   pod/coredns-668d6bf9bc-g2c4j                                Created container: coredns
local-path-storage          43m         Normal    Started                   pod/local-path-provisioner-7dc846544d-9w5nc                 Started container local-path-provisioner
atlas-e2e                   43m         Normal    Pulling                   pod/grafana-7459f79596-vr42j                                Pulling image "grafana/grafana:11.2.0"
atlas-e2e                   43m         Normal    Pulling                   pod/minio-8d4866b9-gk4nn                                    Pulling image "minio/minio:RELEASE.2025-01-20T14-49-07Z"
kube-system                 43m         Normal    Created                   pod/coredns-668d6bf9bc-phnlt                                Created container: coredns
kube-system                 43m         Normal    Pulled                    pod/coredns-668d6bf9bc-g2c4j                                Container image "registry.k8s.io/coredns/coredns:v1.11.3" already present on machine
kube-system                 43m         Normal    Pulled                    pod/coredns-668d6bf9bc-phnlt                                Container image "registry.k8s.io/coredns/coredns:v1.11.3" already present on machine
atlas-e2e                   43m         Normal    Created                   pod/grafana-7459f79596-vr42j                                Created container: grafana
atlas-e2e                   43m         Normal    Pulled                    pod/grafana-7459f79596-vr42j                                Successfully pulled image "grafana/grafana:11.2.0" in 8.694s (8.695s including waiting). Image size: 120038166 bytes.
atlas-e2e                   43m         Normal    Started                   pod/grafana-7459f79596-vr42j                                Started container grafana
atlas-e2e                   43m         Normal    Created                   pod/otel-collector-676699486c-xhdlz                         Created container: otel-collector
atlas-e2e                   43m         Normal    Pulled                    pod/otel-collector-676699486c-xhdlz                         Successfully pulled image "otel/opentelemetry-collector-contrib:0.111.0" in 4.837s (13.528s including waiting). Image size: 67517115 bytes.
atlas-e2e                   43m         Normal    Started                   pod/otel-collector-676699486c-xhdlz                         Started container otel-collector
atlas-e2e                   43m         Normal    Started                   pod/prometheus-77f7b9d779-2zq96                             Started container prometheus
atlas-e2e                   43m         Normal    Pulled                    pod/prometheus-77f7b9d779-2zq96                             Successfully pulled image "prom/prometheus:v2.54.1" in 6.675s (20.201s including waiting). Image size: 102324478 bytes.
atlas-e2e                   43m         Normal    Created                   pod/prometheus-77f7b9d779-2zq96                             Created container: prometheus
atlas-e2e                   43m         Normal    Started                   pod/minio-8d4866b9-gk4nn                                    Started container minio
atlas-e2e                   43m         Normal    Created                   pod/minio-8d4866b9-gk4nn                                    Created container: minio
atlas-e2e                   43m         Normal    Pulled                    pod/minio-8d4866b9-gk4nn                                    Successfully pulled image "minio/minio:RELEASE.2025-01-20T14-49-07Z" in 4.572s (24.773s including waiting). Image size: 58649329 bytes.
atlas-e2e                   43m         Normal    Pulling                   pod/minio-bootstrap                                         Pulling image "minio/mc:RELEASE.2025-01-17T23-25-50Z"
atlas-e2e                   43m         Normal    Scheduled                 pod/minio-bootstrap                                         Successfully assigned atlas-e2e/minio-bootstrap to bijux-atlas-e2e-control-plane
atlas-e2e                   43m         Normal    Pulled                    pod/minio-bootstrap                                         Successfully pulled image "minio/mc:RELEASE.2025-01-17T23-25-50Z" in 3.99s (3.99s including waiting). Image size: 26586064 bytes.
atlas-e2e                   43m         Normal    Created                   pod/minio-bootstrap                                         Created container: minio-bootstrap
atlas-e2e                   43m         Normal    Started                   pod/minio-bootstrap                                         Started container minio-bootstrap
atlas-e2e                   6m5s        Normal    Created                   pod/minio-bootstrap                                         Created container: minio-bootstrap
atlas-e2e                   6m5s        Normal    Started                   pod/minio-bootstrap                                         Started container minio-bootstrap
atlas-e2e                   6m5s        Normal    Pulled                    pod/minio-bootstrap                                         Container image "minio/mc:RELEASE.2025-01-17T23-25-50Z" already present on machine
atlas-e2e                   6m5s        Normal    Scheduled                 pod/minio-bootstrap                                         Successfully assigned atlas-e2e/minio-bootstrap to bijux-atlas-e2e-control-plane
atlas-ops-20260219-175103   5m57s       Normal    SuccessfulCreate          replicaset/atlas-e2e-bijux-atlas-5c5d64d5d5                 Created pod: atlas-e2e-bijux-atlas-5c5d64d5d5-8psr2
atlas-ops-20260219-175103   5m57s       Normal    ScalingReplicaSet         deployment/atlas-e2e-bijux-atlas                            Scaled up replica set atlas-e2e-bijux-atlas-5c5d64d5d5 from 0 to 1
atlas-ops-20260219-175103   5m57s       Normal    Scheduled                 pod/atlas-e2e-bijux-atlas-5c5d64d5d5-8psr2                  Successfully assigned atlas-ops-20260219-175103/atlas-e2e-bijux-atlas-5c5d64d5d5-8psr2 to bijux-atlas-e2e-control-plane
atlas-ops-20260219-175103   5m56s       Normal    Started                   pod/atlas-e2e-bijux-atlas-5c5d64d5d5-8psr2                  Started container atlas-server
atlas-ops-20260219-175103   5m56s       Normal    Created                   pod/atlas-e2e-bijux-atlas-5c5d64d5d5-8psr2                  Created container: atlas-server
atlas-ops-20260219-175103   5m56s       Normal    Pulled                    pod/atlas-e2e-bijux-atlas-5c5d64d5d5-8psr2                  Container image "bijux-atlas:local" already present on machine
atlas-ops-20260219-175103   5m51s       Warning   Unhealthy                 pod/atlas-e2e-bijux-atlas-5c5d64d5d5-8psr2                  Startup probe failed: Get "http://10.244.0.46:8080/healthz": dial tcp 10.244.0.46:8080: connect: connection refused
atlas-e2e                   5m23s       Normal    Scheduled                 pod/minio-bootstrap                                         Successfully assigned atlas-e2e/minio-bootstrap to bijux-atlas-e2e-control-plane
atlas-e2e                   5m22s       Normal    Pulled                    pod/minio-bootstrap                                         Container image "minio/mc:RELEASE.2025-01-17T23-25-50Z" already present on machine
atlas-e2e                   5m22s       Normal    Created                   pod/minio-bootstrap                                         Created container: minio-bootstrap
atlas-e2e                   5m22s       Normal    Started                   pod/minio-bootstrap                                         Started container minio-bootstrap
atlas-e2e                   4m20s       Normal    Started                   pod/minio-bootstrap                                         Started container minio-bootstrap
atlas-e2e                   4m20s       Normal    Created                   pod/minio-bootstrap                                         Created container: minio-bootstrap
atlas-e2e                   4m20s       Normal    Pulled                    pod/minio-bootstrap                                         Container image "minio/mc:RELEASE.2025-01-17T23-25-50Z" already present on machine
atlas-e2e                   4m20s       Normal    Scheduled                 pod/minio-bootstrap                                         Successfully assigned atlas-e2e/minio-bootstrap to bijux-atlas-e2e-control-plane
atlas-e2e                   3m50s       Normal    Scheduled                 pod/minio-bootstrap                                         Successfully assigned atlas-e2e/minio-bootstrap to bijux-atlas-e2e-control-plane
atlas-e2e                   3m50s       Normal    Pulled                    pod/minio-bootstrap                                         Container image "minio/mc:RELEASE.2025-01-17T23-25-50Z" already present on machine
atlas-e2e                   3m50s       Normal    Created                   pod/minio-bootstrap                                         Created container: minio-bootstrap
atlas-e2e                   3m50s       Normal    Started                   pod/minio-bootstrap                                         Started container minio-bootstrap
atlas-e2e                   3m19s       Normal    Scheduled                 pod/minio-bootstrap                                         Successfully assigned atlas-e2e/minio-bootstrap to bijux-atlas-e2e-control-plane
atlas-e2e                   3m18s       Normal    Created                   pod/minio-bootstrap                                         Created container: minio-bootstrap
atlas-e2e                   3m18s       Normal    Pulled                    pod/minio-bootstrap                                         Container image "minio/mc:RELEASE.2025-01-17T23-25-50Z" already present on machine
atlas-e2e                   3m18s       Normal    Started                   pod/minio-bootstrap                                         Started container minio-bootstrap
atlas-e2e                   2m39s       Normal    Scheduled                 pod/minio-bootstrap                                         Successfully assigned atlas-e2e/minio-bootstrap to bijux-atlas-e2e-control-plane
atlas-e2e                   2m39s       Normal    Pulled                    pod/minio-bootstrap                                         Container image "minio/mc:RELEASE.2025-01-17T23-25-50Z" already present on machine
atlas-e2e                   2m39s       Normal    Created                   pod/minio-bootstrap                                         Created container: minio-bootstrap
atlas-e2e                   2m39s       Normal    Started                   pod/minio-bootstrap                                         Started container minio-bootstrap
atlas-e2e                   74s         Normal    Scheduled                 pod/minio-bootstrap                                         Successfully assigned atlas-e2e/minio-bootstrap to bijux-atlas-e2e-control-plane
atlas-e2e                   73s         Normal    Started                   pod/minio-bootstrap                                         Started container minio-bootstrap
atlas-e2e                   73s         Normal    Created                   pod/minio-bootstrap                                         Created container: minio-bootstrap
atlas-e2e                   73s         Normal    Pulled                    pod/minio-bootstrap                                         Container image "minio/mc:RELEASE.2025-01-17T23-25-50Z" already present on machine
atlas-observability         58s         Normal    ScalingReplicaSet         deployment/atlas-observability-prometheus                   Scaled up replica set atlas-observability-prometheus-7595b747b8 from 0 to 1
atlas-observability         58s         Normal    Scheduled                 pod/atlas-observability-grafana-64b9766696-zmqfh            Successfully assigned atlas-observability/atlas-observability-grafana-64b9766696-zmqfh to bijux-atlas-e2e-control-plane
atlas-observability         58s         Normal    ScalingReplicaSet         deployment/atlas-observability-grafana                      Scaled up replica set atlas-observability-grafana-64b9766696 from 0 to 1
atlas-observability         58s         Normal    SuccessfulCreate          replicaset/atlas-observability-grafana-64b9766696           Created pod: atlas-observability-grafana-64b9766696-zmqfh
atlas-observability         58s         Normal    Scheduled                 pod/atlas-observability-prometheus-7595b747b8-pgh2d         Successfully assigned atlas-observability/atlas-observability-prometheus-7595b747b8-pgh2d to bijux-atlas-e2e-control-plane
atlas-observability         58s         Normal    SuccessfulCreate          replicaset/atlas-observability-prometheus-7595b747b8        Created pod: atlas-observability-prometheus-7595b747b8-pgh2d
atlas-observability         57s         Normal    Started                   pod/atlas-observability-otel-cbc899fc-mt82x                 Started container otel-collector
atlas-observability         57s         Normal    Created                   pod/atlas-observability-otel-cbc899fc-mt82x                 Created container: otel-collector
atlas-observability         57s         Normal    Started                   pod/atlas-observability-prometheus-7595b747b8-pgh2d         Started container prometheus
atlas-observability         57s         Normal    Created                   pod/atlas-observability-prometheus-7595b747b8-pgh2d         Created container: prometheus
atlas-observability         57s         Normal    Pulled                    pod/atlas-observability-prometheus-7595b747b8-pgh2d         Container image "prom/prometheus:v2.54.1" already present on machine
atlas-observability         57s         Normal    ScalingReplicaSet         deployment/atlas-observability-otel                         Scaled up replica set atlas-observability-otel-cbc899fc from 0 to 1
atlas-observability         57s         Normal    Created                   pod/atlas-observability-grafana-64b9766696-zmqfh            Created container: grafana
atlas-observability         57s         Normal    Started                   pod/atlas-observability-grafana-64b9766696-zmqfh            Started container grafana
atlas-observability         57s         Normal    Scheduled                 pod/atlas-observability-otel-cbc899fc-mt82x                 Successfully assigned atlas-observability/atlas-observability-otel-cbc899fc-mt82x to bijux-atlas-e2e-control-plane
atlas-observability         57s         Normal    Pulled                    pod/atlas-observability-otel-cbc899fc-mt82x                 Container image "otel/opentelemetry-collector-contrib:0.111.0" already present on machine
atlas-observability         57s         Normal    Pulled                    pod/atlas-observability-grafana-64b9766696-zmqfh            Container image "grafana/grafana:11.2.0" already present on machine
atlas-observability         57s         Normal    SuccessfulCreate          replicaset/atlas-observability-otel-cbc899fc                Created pod: atlas-observability-otel-cbc899fc-mt82x
atlas-e2e                   11s         Normal    Scheduled                 pod/minio-bootstrap                                         Successfully assigned atlas-e2e/minio-bootstrap to bijux-atlas-e2e-control-plane
atlas-e2e                   10s         Normal    Pulled                    pod/minio-bootstrap                                         Container image "minio/mc:RELEASE.2025-01-17T23-25-50Z" already present on machine
atlas-e2e                   10s         Normal    Created                   pod/minio-bootstrap                                         Created container: minio-bootstrap
atlas-e2e                   10s         Normal    Started                   pod/minio-bootstrap                                         Started container minio-bootstrap
